<?xml version="1.0" ?>
<!-- =================================================================================== -->
<!-- |    This document was autogenerated by xacro from model.urdf                     | -->
<!-- |    EDITING THIS FILE BY HAND IS NOT RECOMMENDED                                 | -->
<!-- =================================================================================== -->
<robot name="robot_0">
  <gazebo>
    <plugin filename="libgz-sim-diff-drive-system" name="gz::sim::systems::DiffDrive">
      <left_joint>left_wheel_joint</left_joint>
      <right_joint>right_wheel_joint</right_joint>
      <wheel_separation>0.7</wheel_separation>
      <wheel_radius>0.2</wheel_radius>
      <max_linear_acceleration>1.0</max_linear_acceleration>
      <odom_publish_frequency>30</odom_publish_frequency>
      <topic>/model/robot_0/cmd_vel</topic>
      <tf_topic>/model/robot_0/tf</tf_topic>
      <frame_id>odom</frame_id>
      <child_frame_id>base_link</child_frame_id>
    </plugin>
    <plugin filename="gz-sim-pose-publisher-system" name="gz::sim::systems::PosePublisher">
      <publish_link_pose>false</publish_link_pose>
      <publish_nested_model_pose>true</publish_nested_model_pose>
      <use_pose_vector_msg>true</use_pose_vector_msg>
      <update_frequency>30</update_frequency>
    </plugin>
    <plugin filename="gz-sim-joint-state-publisher-system" name="gz::sim::systems::JointStatePublisher">
      <joint_name>right_wheel_joint</joint_name>
      <joint_name>left_wheel_joint</joint_name>
    </plugin>
  </gazebo>
  <!-- Robot Base -->
  <link name="base_link">
    <visual>
      <geometry>
        <cylinder length="0.4" radius="0.2"/>
      </geometry>
      <material name="Cyan">
        <color rgba="0 0 1.0 1.0"/>
      </material>
    </visual>
    <collision>
      <geometry>
        <cylinder length="0.4" radius="0.2"/>
      </geometry>
    </collision>
    <inertial>
      <origin rpy="1.5707963267948966 0 0" xyz="0 0 0"/>
      <mass value="15"/>
      <inertia ixx="0.35000000000000003" ixy="0" ixz="0" iyy="0.35000000000000003" iyz="0" izz="0.30000000000000004"/>
    </inertial>
  </link>
  <!-- Robot Footprint -->
  <link name="base_footprint">
    <inertial>
      <origin rpy="1.5707963267948966 0 1.5707963267948966" xyz="0 0 0"/>
      <mass value="0"/>
      <inertia ixx="0.0" ixy="0.0" ixz="0.0" iyy="0.0" iyz="0.0" izz="0.0"/>
    </inertial>
  </link>
  <joint name="footprint_joint" type="fixed">
    <parent link="base_link"/>
    <child link="base_footprint"/>
    <origin rpy="0 0 0" xyz="0.0 0.0 -0.05000000000000002"/>
  </joint>
  <link name="left_wheel_link">
    <visual>
      <origin rpy="1.5707963267948966 0 0" xyz="0 0 0"/>
      <geometry>
        <cylinder length="0.1" radius="0.2"/>
      </geometry>
      <material name="Gray">
        <color rgba="0.5 0.5 0.5 1.0"/>
      </material>
    </visual>
    <collision>
      <origin rpy="1.5707963267948966 0 0" xyz="0 0 0"/>
      <geometry>
        <cylinder length="0.1" radius="0.2"/>
      </geometry>
      <surface>
        <friction>
          <ode>
            <mu>100</mu>
            <mu2>100</mu2>
            <slip1>0</slip1>
            <slip2>0</slip2>
          </ode>
        </friction>
      </surface>
    </collision>
    <inertial>
      <origin rpy="1.5707963267948966 0 0" xyz="0 0 0"/>
      <mass value="0.1"/>
      <inertia ixx="0.0010833333333333335" ixy="0" ixz="0" iyy="0.0010833333333333335" iyz="0" izz="0.0020000000000000005"/>
    </inertial>
  </link>
  <joint name="left_wheel_joint" type="continuous">
    <parent link="base_link"/>
    <child link="left_wheel_link"/>
    <origin rpy="0 0 0" xyz="0.0 0.35 -0.15"/>
    <axis xyz="0 1 0"/>
    <limit effort="20" velocity="5"/>
  </joint>
  <link name="right_wheel_link">
    <visual>
      <origin rpy="1.5707963267948966 0 0" xyz="0 0 0"/>
      <geometry>
        <cylinder length="0.1" radius="0.2"/>
      </geometry>
      <material name="Gray">
        <color rgba="0.5 0.5 0.5 1.0"/>
      </material>
    </visual>
    <collision>
      <origin rpy="1.5707963267948966 0 0" xyz="0 0 0"/>
      <geometry>
        <cylinder length="0.1" radius="0.2"/>
      </geometry>
      <surface>
        <friction>
          <ode>
            <mu>100</mu>
            <mu2>100</mu2>
            <slip1>0</slip1>
            <slip2>0</slip2>
          </ode>
        </friction>
      </surface>
    </collision>
    <inertial>
      <origin rpy="1.5707963267948966 0 0" xyz="0 0 0"/>
      <mass value="0.1"/>
      <inertia ixx="0.0010833333333333335" ixy="0" ixz="0" iyy="0.0010833333333333335" iyz="0" izz="0.0020000000000000005"/>
    </inertial>
  </link>
  <joint name="right_wheel_joint" type="continuous">
    <parent link="base_link"/>
    <child link="right_wheel_link"/>
    <origin rpy="0 0 0" xyz="0.0 -0.35 -0.15"/>
    <axis xyz="0 1 0"/>
    <limit effort="20" velocity="5"/>
  </joint>
  <link name="front_left_caster">
    <visual>
      <geometry>
        <sphere radius="0.1"/>
      </geometry>
      <material name="green">
        <color rgba="0 1.0 0 1.0"/>
      </material>
    </visual>
    <collision>
      <origin rpy="0 0 0" xyz="0 0 0"/>
      <geometry>
        <sphere radius="0.1"/>
      </geometry>
    </collision>
  </link>
  <joint name="front_left_caster_joint" type="fixed">
    <parent link="base_link"/>
    <child link="front_left_caster"/>
    <origin rpy="0 0 0" xyz="0.3 0.3 -0.24999999999999997"/>
  </joint>
  <gazebo reference="front_left_caster">
    <collision>
      <surface>
        <friction>
          <ode>
            <mu>0</mu>
            <mu2>0</mu2>
          </ode>
        </friction>
      </surface>
    </collision>
  </gazebo>
  <link name="front_right_caster">
    <visual>
      <geometry>
        <sphere radius="0.1"/>
      </geometry>
      <material name="green">
        <color rgba="0 1.0 0 1.0"/>
      </material>
    </visual>
    <collision>
      <origin rpy="0 0 0" xyz="0 0 0"/>
      <geometry>
        <sphere radius="0.1"/>
      </geometry>
    </collision>
  </link>
  <joint name="front_right_caster_joint" type="fixed">
    <parent link="base_link"/>
    <child link="front_right_caster"/>
    <origin rpy="0 0 0" xyz="0.3 -0.3 -0.24999999999999997"/>
  </joint>
  <gazebo reference="front_right_caster">
    <collision>
      <surface>
        <friction>
          <ode>
            <mu>0</mu>
            <mu2>0</mu2>
          </ode>
        </friction>
      </surface>
    </collision>
  </gazebo>
  <link name="rear_left_caster">
    <visual>
      <geometry>
        <sphere radius="0.1"/>
      </geometry>
      <material name="green">
        <color rgba="0 1.0 0 1.0"/>
      </material>
    </visual>
    <collision>
      <origin rpy="0 0 0" xyz="0 0 0"/>
      <geometry>
        <sphere radius="0.1"/>
      </geometry>
    </collision>
  </link>
  <joint name="rear_left_caster_joint" type="fixed">
    <parent link="base_link"/>
    <child link="rear_left_caster"/>
    <origin rpy="0 0 0" xyz="-0.3 0.3 -0.24999999999999997"/>
  </joint>
  <gazebo reference="rear_left_caster">
    <collision>
      <surface>
        <friction>
          <ode>
            <mu>0</mu>
            <mu2>0</mu2>
          </ode>
        </friction>
      </surface>
    </collision>
  </gazebo>
  <link name="rear_right_caster">
    <visual>
      <geometry>
        <sphere radius="0.1"/>
      </geometry>
      <material name="green">
        <color rgba="0 1.0 0 1.0"/>
      </material>
    </visual>
    <collision>
      <origin rpy="0 0 0" xyz="0 0 0"/>
      <geometry>
        <sphere radius="0.1"/>
      </geometry>
    </collision>
  </link>
  <joint name="rear_right_caster_joint" type="fixed">
    <parent link="base_link"/>
    <child link="rear_right_caster"/>
    <origin rpy="0 0 0" xyz="-0.3 -0.3 -0.24999999999999997"/>
  </joint>
  <gazebo reference="rear_right_caster">
    <collision>
      <surface>
        <friction>
          <ode>
            <mu>0</mu>
            <mu2>0</mu2>
          </ode>
        </friction>
      </surface>
    </collision>
  </gazebo>
  <link name="orientation_link">
    <visual>
      <origin rpy="0 0 0" xyz="0 0 0"/>
      <geometry>
        <box size="0.22000000000000003 0.1 0.05"/>
      </geometry>
      <material name="cyan">
        <color rgba="0 1.0 1.0 1.0"/>
      </material>
    </visual>
    <collision>
      <origin rpy="0 0 0" xyz="0 0 0"/>
      <geometry>
        <box size="0.22000000000000003 0.1 0.05"/>
      </geometry>
    </collision>
    <inertial>
      <origin rpy="1.5707963267948966 0 1.5707963267948966" xyz="0 0 0"/>
      <mass value="0.01"/>
      <inertia ixx="1.041666666666667e-05" ixy="0.0" ixz="0.0" iyy="4.866666666666668e-05" iyz="0.0" izz="4.2416666666666684e-05"/>
    </inertial>
  </link>
  <joint name="orientation_joint" type="fixed">
    <parent link="base_link"/>
    <child link="orientation_link"/>
    <origin rpy="0 0 0" xyz="0.09 0 0.2"/>
  </joint>
  <!-- LIDAR -->
  <link name="lidar_link">
    <inertial>
      <origin rpy="1.5707963267948966 0 0" xyz="0 0 0"/>
      <mass value="0.125"/>
      <inertia ixx="0.001015625" ixy="0" ixz="0" iyy="0.001015625" iyz="0" izz="0.00015625000000000003"/>
    </inertial>
    <collision>
      <origin rpy="0 0 0" xyz="0 0 0"/>
      <geometry>
        <cylinder length="0.3" radius="0.05"/>
      </geometry>
    </collision>
    <visual>
      <origin rpy="0 0 0" xyz="0 0 0"/>
      <geometry>
        <cylinder length="0.3" radius="0.05"/>
      </geometry>
    </visual>
  </link>
  <joint name="lidar_joint" type="continuous">
    <parent link="base_link"/>
    <child link="lidar_link"/>
    <origin rpy="0 0 0" xyz="0.0 0.0 1.0"/>
  </joint>
  <gazebo reference="lidar_link">
    <frame attached_to="lidar_link" name="lidar_frame">
      <pose>0.8 0 0.5 0 0 0</pose>
    </frame>
    <sensor name="gpu_lidar" type="gpu_lidar">
      <pose relative_to="lidar_link">0 0 0 0 0 0</pose>
      <topic>
        scan</topic>
      <update_rate>30</update_rate>
      <gz_frame_id>lidar_link</gz_frame_id>
      <ray>
        <scan>
          <horizontal>
            <samples>360</samples>
            <resolution>1</resolution>
            <min_angle>-3.14159</min_angle>
            <max_angle>3.14159</max_angle>
          </horizontal>
          <vertical>
            <samples>1</samples>
            <resolution>0.01</resolution>
            <min_angle>0</min_angle>
            <max_angle>0</max_angle>
          </vertical>
        </scan>
        <range>
          <min>0.08</min>
          <max>10.0</max>
          <resolution>0.01</resolution>
        </range>
      </ray>
      <always_on>true</always_on>
      <visualize>
        true</visualize>
    </sensor>
  </gazebo>
</robot>
